Workbook
Name ifw_edit_options_1478993052: #REF!
Name ifw_edit_title_1478993052: #REF!
Name ifw_edit_description_1478993052: #REF!
Name ifw_edit_urls_1_1478993052: #REF!
Name ifw_edit_selectors_1_1478993052: #REF!

Sheet Elevators
A1: Station | B1: Services | C1: Division | D1: Line | E1: ♿ / ❌ | F1: IF NOT, ARE THERE ANY OFFICAL PLANS TO DO SO? IF NOT, POSSIBLE REASONS? | G1: DATE MADE FIRST ACCESSIBLE | H1: SOURCES | I1: Opened | J1: Borough | K1: Neighborhood | L1: Ridership (2024) | M1: Rank
A2: 1 Av | B2: L | C2: BMT | D2: Canarsie Line | E2: ♿ | G2: August 6, 2020 | H2: MTA Officials Announce Opening of New Elevators at Two L Train Stations and Join Accessibility Advocates to Call for Urgently Needed Federal Funding | I2: 8948 | J2: Manhattan | K2: East Village | L2: 6266103 | M2: 35
A3: 125 St | B3: 1 | C3: IRT | D3: Broadway-7 Av Line | E3: ♿ | I3: 1762 | J3: Manhattan | K3: Manhattanville | L3: 1977586 | M3: 165
A4: 125 St | B4: A,B,C,D | C4: IND | D4: 8 Av Line | E4: ♿ | G4: 2000 | I4: 11942 | J4: Manhattan | K4: Harlem | L4: 5853749 | M4: 45
A5: 125 St | B5: 4,5,6 | C5: IRT | D5: Lexington Av Line | E5: ♿ | I5: 6773 | J5: Manhattan | K5: East Harlem | L5: 5425934 | M5: 51
A6: 135 St | B6: 2,3 | C6: IRT | D6: Lenox Av Line | E6: ♿ | I6: 1789 | J6: Manhattan | K6: Harlem | L6: 2237928 | M6: 149
A7: 14 St-Union Sq | B7: N,Q,R,W | C7: BMT | D7: Broadway Line | E7: ♿ | G7: 2000 | I7: 6457 | J7: Manhattan | K7: Union Square | L7: 22811597 | M7: 4
A8: 14 St-Union Sq | B8: L | C8: BMT | D8: Canarsie Line | E8: ♿ | G8: 2000 | I8: 8948 | J8: Manhattan | K8: Union Square | L8: 22811597 | M8: 4
A9: 14 St/6 Av | B9: F,M | C9: IND | D9: 6 Av Line | E9: ♿ | I9: 14960 | J9: Manhattan | K9: Chelsea | L9: 10463838 | M9: 19
A10: 14 St/Eighth Av | B10: L | C10: BMT | D10: Canarsie Line | E10: ♿ | I10: 11473 | J10: Manhattan | K10: Chelsea | L10: 11672402 | M10: 15
A11: 14 St/Eighth Av | B11: A,C,E | C11: IND | D11: 8 Av Line | E11: ♿ | I11: 11942 | J11: Manhattan | K11: Chelsea | L11: 11672402 | M11: 15
A12: 14 St/Sixth Av | B12: 1,2,3 | C12: IRT | D12: Broadway-7 Av Line | E12: ♿ | I12: 6757 | J12: Manhattan | K12: Chelsea | L12: 10463838 | M12: 19
A13: 14 St/Sixth Av | B13: L | C13: BMT | D13: Canarsie Line | E13: ♿ | I13: 8948 | J13: Manhattan | K13: Chelsea | L13: 10463838 | M13: 19
A14: 161 St-Yankee Stadium | B14: B, D | C14: IND | D14: Concourse Line | E14: ♿ | G14: late 2002 | I14: 12236 | J14: The Bronx | K14: Highbridge | L14: 5964943 | M14: 41
A15: 161 St-Yankee Stadium | B15: 4 | C15: IRT | D15: Jerome Av Line | E15: ♿ | G15: late 2002 | I15: 6363 | J15: The Bronx | K15: Highbridge
A16: 170 St | B16: 4 | C16: IRT | D16: Jerome Av Line | E16: ♿ | I16: 6363 | J16: The Bronx | K16: Highbridge | L16: 1396033 | M16: 228
A17: 175 St | B17: A | C17: IND | D17: 8 Av Line | E17: ♿ | G17: November 1989 (?) | I17: 11942 | J17: Manhattan | K17: Washington Heights | L17: 2284232 | M17: 142
A18: 181 St | B18: A | C18: IND | D18: 8 Av Line | E18: ♿ | I18: 11942 | J18: Manhattan | K18: Washington Heights | L18: 2042771 | M18: 160
A19: 207 St | B19: 1 | C19: IRT | D19: Broadway-7 Av Line | E19: ♿ | G19: Late 1990s | I19: 2648 | J19: Manhattan | K19: Inwood | L19: 1244261 | M19: 248
A20: 21 St-Queensbridge | B20: M | C20: IND | D20: 63rd St Line | E20: ♿ | I20: 32810 | J20: Queens | K20: Long Island City | L20: 1751180 | M20: 184
A21: 23 St-Baruch College | B21: 6 | C21: IRT | D21: Lexington Av Line | E21: ♿ | I21: 1762 | J21: Manhattan | K21: Gramercy | L21: 5594512 | M21: 48
A22: 231 St | B22: 1 | C22: IRT | D22: Broadway-7 Av Line | E22: ♿ | I22: 2584 | J22: The Bronx | K22: Kingsbridge | L22: 1780122 | M22: 180
A23: 233 St | B23: 2 | C23: IRT | D23: White Plains Rd Line | E23: ♿ | I23: 6300 | J23: The Bronx | K23: Wakefield | L23: 725758 | M23: 342
A24: 3 Av-149 St | B24: 2,5 | C24: IRT | D24: White Plains Rd Line | E24: ♿ | I24: 2018 | J24: The Bronx | K24: Mott Haven | L24: 3698741 | M24: 87
A25: 34 St-Herald Sq | B25: N,Q,R,W | C25: BMT | D25: Broadway Line | E25: ♿ | G25: 1996 | I25: 6580 | J25: Manhattan | K25: Midtown | L25: 25012549 | M25: 3
A26: 34 St-Herald Sq | B26: B,D,F,M | C26: IND | D26: 6 Av Line | E26: ♿ | G26: 1996 | I26: 14960 | J26: Manhattan | K26: Midtown | L26: 25012549 | M26: 3
A27: 34 St-Hudson Yards | B27: 7 | C27: IRT | D27: Flushing Line | E27: ♿ | I27: 42260 | J27: Manhattan | K27: Hell's Kitchen | L27: 6082370 | M27: 39
A28: 34 St-Penn Station | B28: 1,2,3 | C28: IRT | D28: Broadway-7 Av Line | E28: ♿ | G28: 1990s | I28: 6364 | J28: Manhattan | K28: Midtown | L28: 16373975 | M28: 8
A29: 34 St-Penn Station | B29: A,C,E | C29: IND | D29: 8 Av Line | E29: ♿ | G29: 1990s | I29: 11942 | J29: Manhattan | K29: Midtown | L29: 18393456 | M29: 6
A30: 42 St-Port Authority Bus Terminal | B30: A,C,E | C30: IND | D30: 8 Av Line | E30: ♿ | G30: 1990s | I30: 11942 | J30: Manhattan | K30: Midtown | L30: 57743486 | M30: 1
A31: 47-50 Sts-Rockefeller Center | B31: B,D,F,M | C31: IND | D31: 6 Av Line | E31: ♿ | G31: 1994-1996 | I31: 14960 | J31: Manhattan | K31: Midtown | L31: 12514970 | M31: 13
A32: 5 Av/53 St | B32: E,F | C32: IND | D32: Queens Blvd Line | E32: ♿ | I32: 12359 | J32: Manhattan | K32: Midtown | L32: 4590651 | M32: 64
A33: 57 St-7 Av | B33: N,Q,R,W | C33: BMT | D33: Broadway Line | E33: ♿ | G33: June 1, 2021 | H33: Midtown Manhattan's 57 St NQRW Station Now Accessible to All Riders | MTA | I33: 7131 | J33: Manhattan | K33: Midtown | L33: 8342178 | M33: 24
A34: 59 St | B34: N,R | C34: BMT | D34: 4 Av Line | E34: ♿ | G34: November 9, 2020 | H34: MTA Unveils New Fully Accessible Station in Brooklyn | I34: 5652 | J34: Brooklyn | K34: Sunset Park | L34: 2952891 | M34: 112
A35: 59 St-Columbus Circle | B35: 1 | C35: IRT | D35: Broadway-7 Av Line | E35: ♿ | G35: 2011 | I35: 1762 | J35: Manhattan | K35: Midtown | L35: 16884912 | M35: 7
A36: 59 St-Columbus Circle | B36: A,B,C,D | C36: IND | D36: 8 Av Line | E36: ♿ | G36: 2011 | I36: 11942 | J36: Manhattan | K36: Midtown | L36: 16884912 | M36: 7
A37: 61 St-Woodside | B37: 7 | C37: IRT | D37: Flushing Line | E37: ♿ | I37: 6321 | J37: Queens | K37: Woodside | L37: 3808140 | M37: 83
A38: 62 St/New Utrecht Av | B38: N | C38: BMT | D38: Sea Beach Line | E38: ♿ | G38: July 19, 2019 | H38: New Utrecht Av/62 St ADA project | The Metropolitan Transpor… | Flickr | I38: 5652 | J38: Brooklyn | K38: Borough Park | L38: 1152489 | M38: 266
A39: 62 St/New Utrecht Av | B39: D | C39: BMT | D39: West End Line | E39: ♿ | G39: July 19, 2019 | H39: New Utrecht Av/62 St ADA project | The Metropolitan Transpor… | Flickr | I39: 6020 | J39: Brooklyn | K39: Borough Park | L39: 1152489 | M39: 266
A40: 66 St-Lincoln Center | B40: 1 | C40: IRT | D40: Broadway-7 Av Line | E40: ♿ | I40: 1762 | J40: Manhattan | K40: Upper West Side | L40: 4774721 | M40: 60
...

Sheet Escalators
A1: Station | B1: Line | C1: Borough | D1: Neighborhood | E1: Opened | F1: Ridership (2024) | G1: Rank | H1: ↗️ / ❌ | I1: Original Installation Date | J1: Latest Installation Date | K1: Service Life | L1: NYCT Owned | M1: Maintained By | N1: Installer | O1: Revenue Machine | P1: Street Access | Q1: Exposed to Weather | R1: Escalator Rise | S1: Escalator Number of Steps | T1: Escalator Step Width | U1: Notes | V1: Georeference
A2: =IFERROR(__xludf.DUMMYFUNCTION("FILTER(ARRAYFORMULA({SUBSTITUTE(Sheet5!D2:D1494, "" - Station"", """"), IFERROR(VLOOKUP(SUBSTITUTE(Sheet5!D2:D1494, "" - Station"", """"), Elevators!A:M, 4, FALSE), """"), IFERROR(VLOOKUP(SUBSTITUTE(Sheet5!D2:D1494, "" - Station"", """"), Elevators!A:M, 1"&"0, FALSE), """"), IFERROR(VLOOKUP(SUBSTITUTE(Sheet5!D2:D1494, "" - Station"", """"), Elevators!A:M, 11, FALSE), """"), IFERROR(VLOOKUP(SUBSTITUTE(Sheet5!D2:D1494, "" - Station"", """"), Elevators!A:M, 9, FALSE), """"), IFERROR(VLOOKUP(SUBSTITUTE(Sheet5!D2"&":D1494, "" - Station"", """"), Elevators!A:M, 12, FALSE), """"), IFERROR(VLOOKUP(SUBSTITUTE(Sheet5!D2:D1494, "" - Station"", """"), Elevators!A:M, 13, FALSE), """"), IF(Sheet5!L2:L1494=""Removed-Non Functioning-Out of Service"", ""❌"", ""↗️""), Sheet5!I2:"&"I1494, Sheet5!J2:J1494, Sheet5!M2:M1494, Sheet5!N2:N1494, Sheet5!O2:O1494, Sheet5!P2:P1494, Sheet5!Q2:Q1494, Sheet5!S2:S1494, Sheet5!T2:T1494, Sheet5!U2:U1494, Sheet5!Z2:Z1494, Sheet5!AA2:AA1494, Sheet5!AG2:AG1494, Sheet5!AN2:AN1494}), Sheet5!B2:B1494=""E"&"scalator"")"),"Lexington Av/53 St") -> Lexington Av/53 St | B2: =IFERROR(__xludf.DUMMYFUNCTION("""COMPUTED_VALUE"""),"") | C2: =IFERROR(__xludf.DUMMYFUNCTION("""COMPUTED_VALUE"""),"") | D2: =IFERROR(__xludf.DUMMYFUNCTION("""COMPUTED_VALUE"""),"") | E2: =IFERROR(__xludf.DUMMYFUNCTION("""COMPUTED_VALUE"""),"") | F2: =IFERROR(__xludf.DUMMYFUNCTION("""COMPUTED_VALUE"""),"") | G2: =IFERROR(__xludf.DUMMYFUNCTION("""COMPUTED_VALUE"""),"") | H2: =IFERROR(__xludf.DUMMYFUNCTION("""COMPUTED_VALUE"""),"↗️") -> ↗️ | J2: =IFERROR(__xludf.DUMMYFUNCTION("""COMPUTED_VALUE"""),3.0) -> 3 | K2: =IFERROR(__xludf.DUMMYFUNCTION("""COMPUTED_VALUE"""),22.0) -> 22 | L2: =IFERROR(__xludf.DUMMYFUNCTION("""COMPUTED_VALUE"""),"NO") -> NO | M2: =IFERROR(__xludf.DUMMYFUNCTION("""COMPUTED_VALUE"""),"Private Contractor") -> Private Contractor | N2: =IFERROR(__xludf.DUMMYFUNCTION("""COMPUTED_VALUE"""),"AM") -> AM | O2: =IFERROR(__xludf.DUMMYFUNCTION("""COMPUTED_VALUE"""),"YES") -> YES | P2: =IFERROR(__xludf.DUMMYFUNCTION("""COMPUTED_VALUE"""),"NO") -> NO | Q2: =IFERROR(__xludf.DUMMYFUNCTION("""COMPUTED_VALUE"""),"NO") -> NO | U2: =IFERROR(__xludf.DUMMYFUNCTION("""COMPUTED_VALUE"""),"6/E/F mezzanine to 52 St & Lexington Av (NE corner).") -> 6/E/F mezzanine to 52 St & Lexington Av (NE corner). | V2: =IFERROR(__xludf.DUMMYFUNCTION("""COMPUTED_VALUE"""),"POINT (-73.970924 40.75814)") -> POINT (-73.970924 40.75814)
A3: =IFERROR(__xludf.DUMMYFUNCTION("""COMPUTED_VALUE"""),"34 St-Hudson Yards") -> 34 St-Hudson Yards | B3: =IFERROR(__xludf.DUMMYFUNCTION("""COMPUTED_VALUE"""),"Flushing Line") -> Flushing Line | C3: =IFERROR(__xludf.DUMMYFUNCTION("""COMPUTED_VALUE"""),"Manhattan") -> Manhattan | D3: =IFERROR(__xludf.DUMMYFUNCTION("""COMPUTED_VALUE"""),"Hell's Kitchen") -> Hell's Kitchen | E3: =IFERROR(__xludf.DUMMYFUNCTION("""COMPUTED_VALUE"""),42260.0) -> 42260 | F3: =IFERROR(__xludf.DUMMYFUNCTION("""COMPUTED_VALUE"""),6082370.0) -> 6082370 | G3: =IFERROR(__xludf.DUMMYFUNCTION("""COMPUTED_VALUE"""),39.0) -> 39 | H3: =IFERROR(__xludf.DUMMYFUNCTION("""COMPUTED_VALUE"""),"↗️") -> ↗️ | I3: =IFERROR(__xludf.DUMMYFUNCTION("""COMPUTED_VALUE"""),42260.0) -> 42260 | J3: =IFERROR(__xludf.DUMMYFUNCTION("""COMPUTED_VALUE"""),42260.0) -> 42260 | K3: =IFERROR(__xludf.DUMMYFUNCTION("""COMPUTED_VALUE"""),22.0) -> 22 | L3: =IFERROR(__xludf.DUMMYFUNCTION("""COMPUTED_VALUE"""),"YES") -> YES | M3: =IFERROR(__xludf.DUMMYFUNCTION("""COMPUTED_VALUE"""),"NYCT") -> NYCT | N3: =IFERROR(__xludf.DUMMYFUNCTION("""COMPUTED_VALUE"""),"KONE") -> KONE | O3: =IFERROR(__xludf.DUMMYFUNCTION("""COMPUTED_VALUE"""),"YES") -> YES | P3: =IFERROR(__xludf.DUMMYFUNCTION("""COMPUTED_VALUE"""),"YES") -> YES | Q3: =IFERROR(__xludf.DUMMYFUNCTION("""COMPUTED_VALUE"""),"YES") -> YES | R3: =IFERROR(__xludf.DUMMYFUNCTION("""COMPUTED_VALUE"""),"30'") -> 30' | S3: =IFERROR(__xludf.DUMMYFUNCTION("""COMPUTED_VALUE"""),110.0) -> 110 | T3: =IFERROR(__xludf.DUMMYFUNCTION("""COMPUTED_VALUE"""),24.0) -> 24 | U3: =IFERROR(__xludf.DUMMYFUNCTION("""COMPUTED_VALUE"""),"Hudson Blvd E (between 33 St & 34 St) to upper mezzanine") -> Hudson Blvd E (between 33 St & 34 St) to upper mezzanine | V3: =IFERROR(__xludf.DUMMYFUNCTION("""COMPUTED_VALUE"""),"POINT (-74.00103 40.754982)") -> POINT (-74.00103 40.754982)
A4: =IFERROR(__xludf.DUMMYFUNCTION("""COMPUTED_VALUE"""),"Fulton St") -> Fulton St | B4: =IFERROR(__xludf.DUMMYFUNCTION("""COMPUTED_VALUE"""),"Broadway-7 Av Line") -> Broadway-7 Av Line | C4: =IFERROR(__xludf.DUMMYFUNCTION("""COMPUTED_VALUE"""),"Manhattan") -> Manhattan | D4: =IFERROR(__xludf.DUMMYFUNCTION("""COMPUTED_VALUE"""),"Financial District") -> Financial District | E4: =IFERROR(__xludf.DUMMYFUNCTION("""COMPUTED_VALUE"""),6757.0) -> 6757 | F4: =IFERROR(__xludf.DUMMYFUNCTION("""COMPUTED_VALUE"""),1.9221396E7) -> 19221396 | G4: =IFERROR(__xludf.DUMMYFUNCTION("""COMPUTED_VALUE"""),5.0) -> 5 | H4: =IFERROR(__xludf.DUMMYFUNCTION("""COMPUTED_VALUE"""),"↗️") -> ↗️ | J4: =IFERROR(__xludf.DUMMYFUNCTION("""COMPUTED_VALUE"""),41110.0) -> 41110 | K4: =IFERROR(__xludf.DUMMYFUNCTION("""COMPUTED_VALUE"""),22.0) -> 22 | L4: =IFERROR(__xludf.DUMMYFUNCTION("""COMPUTED_VALUE"""),"NO") -> NO | M4: =IFERROR(__xludf.DUMMYFUNCTION("""COMPUTED_VALUE"""),"Private Contractor") -> Private Contractor | N4: =IFERROR(__xludf.DUMMYFUNCTION("""COMPUTED_VALUE"""),"OTIS") -> OTIS | O4: =IFERROR(__xludf.DUMMYFUNCTION("""COMPUTED_VALUE"""),"YES") -> YES | P4: =IFERROR(__xludf.DUMMYFUNCTION("""COMPUTED_VALUE"""),"NO") -> NO | Q4: =IFERROR(__xludf.DUMMYFUNCTION("""COMPUTED_VALUE"""),"NO") -> NO | U4: =IFERROR(__xludf.DUMMYFUNCTION("""COMPUTED_VALUE"""),"Broad St-bound J/Z platform to Nassau St (between Maiden Lane & John St)") -> Broad St-bound J/Z platform to Nassau St (between Maiden Lane & John St) | V4: =IFERROR(__xludf.DUMMYFUNCTION("""COMPUTED_VALUE"""),"POINT (-74.008354 40.70928)") -> POINT (-74.008354 40.70928)
A5: =IFERROR(__xludf.DUMMYFUNCTION("""COMPUTED_VALUE"""),"96 St") -> 96 St | B5: =IFERROR(__xludf.DUMMYFUNCTION("""COMPUTED_VALUE"""),"Broadway-7 Av Line") -> Broadway-7 Av Line | C5: =IFERROR(__xludf.DUMMYFUNCTION("""COMPUTED_VALUE"""),"Manhattan") -> Manhattan | D5: =IFERROR(__xludf.DUMMYFUNCTION("""COMPUTED_VALUE"""),"Upper West Side") -> Upper West Side | E5: =IFERROR(__xludf.DUMMYFUNCTION("""COMPUTED_VALUE"""),1762.0) -> 1762 | F5: =IFERROR(__xludf.DUMMYFUNCTION("""COMPUTED_VALUE"""),8250940.0) -> 8250940 | G5: =IFERROR(__xludf.DUMMYFUNCTION("""COMPUTED_VALUE"""),26.0) -> 26 | H5: =IFERROR(__xludf.DUMMYFUNCTION("""COMPUTED_VALUE"""),"↗️") -> ↗️ | I5: =IFERROR(__xludf.DUMMYFUNCTION("""COMPUTED_VALUE"""),42736.0) -> 42736 | J5: =IFERROR(__xludf.DUMMYFUNCTION("""COMPUTED_VALUE"""),42736.0) -> 42736 | K5: =IFERROR(__xludf.DUMMYFUNCTION("""COMPUTED_VALUE"""),22.0) -> 22 | L5: =IFERROR(__xludf.DUMMYFUNCTION("""COMPUTED_VALUE"""),"YES") -> YES | M5: =IFERROR(__xludf.DUMMYFUNCTION("""COMPUTED_VALUE"""),"NYCT") -> NYCT | N5: =IFERROR(__xludf.DUMMYFUNCTION("""COMPUTED_VALUE"""),"KONE") -> KONE | O5: =IFERROR(__xludf.DUMMYFUNCTION("""COMPUTED_VALUE"""),"YES") -> YES | P5: =IFERROR(__xludf.DUMMYFUNCTION("""COMPUTED_VALUE"""),"NO") -> NO | Q5: =IFERROR(__xludf.DUMMYFUNCTION("""COMPUTED_VALUE"""),"NO") -> NO | R5: =IFERROR(__xludf.DUMMYFUNCTION("""COMPUTED_VALUE"""),"5042mm (16' 6 1/2in)") -> 5042mm (16' 6 1/2in) | S5: =IFERROR(__xludf.DUMMYFUNCTION("""COMPUTED_VALUE"""),76.0) -> 76 | T5: =IFERROR(__xludf.DUMMYFUNCTION("""COMPUTED_VALUE"""),"1000 mm (39 3/8in)") -> 1000 mm (39 3/8in) | U5: =IFERROR(__xludf.DUMMYFUNCTION("""COMPUTED_VALUE"""),"platform to mezzanine") -> platform to mezzanine | V5: =IFERROR(__xludf.DUMMYFUNCTION("""COMPUTED_VALUE"""),"POINT (-73.94761 40.783447)") -> POINT (-73.94761 40.783447)
A6: =IFERROR(__xludf.DUMMYFUNCTION("""COMPUTED_VALUE"""),"Roosevelt Island") -> Roosevelt Island | B6: =IFERROR(__xludf.DUMMYFUNCTION("""COMPUTED_VALUE"""),"63rd St Line") -> 63rd St Line | C6: =IFERROR(__xludf.DUMMYFUNCTION("""COMPUTED_VALUE"""),"Manhattan") -> Manhattan | D6: =IFERROR(__xludf.DUMMYFUNCTION("""COMPUTED_VALUE"""),"Roosevelt Island") -> Roosevelt Island | E6: =IFERROR(__xludf.DUMMYFUNCTION("""COMPUTED_VALUE"""),32810.0) -> 32810 | F6: =IFERROR(__xludf.DUMMYFUNCTION("""COMPUTED_VALUE"""),1885823.0) -> 1885823 | G6: =IFERROR(__xludf.DUMMYFUNCTION("""COMPUTED_VALUE"""),171.0) -> 171 | H6: =IFERROR(__xludf.DUMMYFUNCTION("""COMPUTED_VALUE"""),"↗️") -> ↗️ | I6: =IFERROR(__xludf.DUMMYFUNCTION("""COMPUTED_VALUE"""),32782.0) -> 32782 | J6: =IFERROR(__xludf.DUMMYFUNCTION("""COMPUTED_VALUE"""),39405.0) -> 39405 | K6: =IFERROR(__xludf.DUMMYFUNCTION("""COMPUTED_VALUE"""),22.0) -> 22 | L6: =IFERROR(__xludf.DUMMYFUNCTION("""COMPUTED_VALUE"""),"YES") -> YES | M6: =IFERROR(__xludf.DUMMYFUNCTION("""COMPUTED_VALUE"""),"NYCT") -> NYCT | N6: =IFERROR(__xludf.DUMMYFUNCTION("""COMPUTED_VALUE"""),"KONE") -> KONE | O6: =IFERROR(__xludf.DUMMYFUNCTION("""COMPUTED_VALUE"""),"YES") -> YES | P6: =IFERROR(__xludf.DUMMYFUNCTION("""COMPUTED_VALUE"""),"NO") -> NO | Q6: =IFERROR(__xludf.DUMMYFUNCTION("""COMPUTED_VALUE"""),"NO") -> NO | R6: =IFERROR(__xludf.DUMMYFUNCTION("""COMPUTED_VALUE"""),"36'") -> 36' | S6: =IFERROR(__xludf.DUMMYFUNCTION("""COMPUTED_VALUE"""),129.0) -> 129 | T6: =IFERROR(__xludf.DUMMYFUNCTION("""COMPUTED_VALUE"""),40.0) -> 40 | U6: =IFERROR(__xludf.DUMMYFUNCTION("""COMPUTED_VALUE"""),"intermediate mezzanine to lower mezzanine") -> intermediate mezzanine to lower mezzanine | V6: =IFERROR(__xludf.DUMMYFUNCTION("""COMPUTED_VALUE"""),"POINT (-73.952866 40.7589)") -> POINT (-73.952866 40.7589)
A7: =IFERROR(__xludf.DUMMYFUNCTION("""COMPUTED_VALUE"""),"Bowling Green") -> Bowling Green | B7: =IFERROR(__xludf.DUMMYFUNCTION("""COMPUTED_VALUE"""),"Lexington Av Line") -> Lexington Av Line | C7: =IFERROR(__xludf.DUMMYFUNCTION("""COMPUTED_VALUE"""),"Manhattan") -> Manhattan | D7: =IFERROR(__xludf.DUMMYFUNCTION("""COMPUTED_VALUE"""),"Financial District") -> Financial District | E7: =IFERROR(__xludf.DUMMYFUNCTION("""COMPUTED_VALUE"""),2018.0) -> 2018 | F7: =IFERROR(__xludf.DUMMYFUNCTION("""COMPUTED_VALUE"""),4676646.0) -> 4676646 | G7: =IFERROR(__xludf.DUMMYFUNCTION("""COMPUTED_VALUE"""),62.0) -> 62 | H7: =IFERROR(__xludf.DUMMYFUNCTION("""COMPUTED_VALUE"""),"↗️") -> ↗️ | I7: =IFERROR(__xludf.DUMMYFUNCTION("""COMPUTED_VALUE"""),28216.0) -> 28216 | J7: =IFERROR(__xludf.DUMMYFUNCTION("""COMPUTED_VALUE"""),38062.0) -> 38062 | K7: =IFERROR(__xludf.DUMMYFUNCTION("""COMPUTED_VALUE"""),22.0) -> 22 | L7: =IFERROR(__xludf.DUMMYFUNCTION("""COMPUTED_VALUE"""),"YES") -> YES | M7: =IFERROR(__xludf.DUMMYFUNCTION("""COMPUTED_VALUE"""),"NYCT") -> NYCT | N7: =IFERROR(__xludf.DUMMYFUNCTION("""COMPUTED_VALUE"""),"FUJITEC") -> FUJITEC | O7: =IFERROR(__xludf.DUMMYFUNCTION("""COMPUTED_VALUE"""),"YES") -> YES | P7: =IFERROR(__xludf.DUMMYFUNCTION("""COMPUTED_VALUE"""),"NO") -> NO | Q7: =IFERROR(__xludf.DUMMYFUNCTION("""COMPUTED_VALUE"""),"NO") -> NO | R7: =IFERROR(__xludf.DUMMYFUNCTION("""COMPUTED_VALUE"""),"20'") -> 20' | S7: =IFERROR(__xludf.DUMMYFUNCTION("""COMPUTED_VALUE"""),80.0) -> 80 | T7: =IFERROR(__xludf.DUMMYFUNCTION("""COMPUTED_VALUE"""),40.0) -> 40 | U7: =IFERROR(__xludf.DUMMYFUNCTION("""COMPUTED_VALUE"""),"lower mezzanine to upper mezzanine for Battery Pl & Broadway exit") -> lower mezzanine to upper mezzanine for Battery Pl & Broadway exit | V7: =IFERROR(__xludf.DUMMYFUNCTION("""COMPUTED_VALUE"""),"POINT (-74.01438 40.70474)") -> POINT (-74.01438 40.70474)
A8: =IFERROR(__xludf.DUMMYFUNCTION("""COMPUTED_VALUE"""),"Times Sq-42 St") -> Times Sq-42 St | B8: =IFERROR(__xludf.DUMMYFUNCTION("""COMPUTED_VALUE"""),"42nd St Line") -> 42nd St Line | C8: =IFERROR(__xludf.DUMMYFUNCTION("""COMPUTED_VALUE"""),"Manhattan") -> Manhattan | D8: =IFERROR(__xludf.DUMMYFUNCTION("""COMPUTED_VALUE"""),"Times Square") -> Times Square | E8: =IFERROR(__xludf.DUMMYFUNCTION("""COMPUTED_VALUE"""),1762.0) -> 1762 | F8: =IFERROR(__xludf.DUMMYFUNCTION("""COMPUTED_VALUE"""),5.7743486E7) -> 57743486 | G8: =IFERROR(__xludf.DUMMYFUNCTION("""COMPUTED_VALUE"""),1.0) -> 1 | H8: =IFERROR(__xludf.DUMMYFUNCTION("""COMPUTED_VALUE"""),"↗️") -> ↗️ | I8: =IFERROR(__xludf.DUMMYFUNCTION("""COMPUTED_VALUE"""),9935.0) -> 9935 | J8: =IFERROR(__xludf.DUMMYFUNCTION("""COMPUTED_VALUE"""),38934.0) -> 38934 | K8: =IFERROR(__xludf.DUMMYFUNCTION("""COMPUTED_VALUE"""),22.0) -> 22 | L8: =IFERROR(__xludf.DUMMYFUNCTION("""COMPUTED_VALUE"""),"YES") -> YES | M8: =IFERROR(__xludf.DUMMYFUNCTION("""COMPUTED_VALUE"""),"NYCT") -> NYCT | N8: =IFERROR(__xludf.DUMMYFUNCTION("""COMPUTED_VALUE"""),"KONE") -> KONE | O8: =IFERROR(__xludf.DUMMYFUNCTION("""COMPUTED_VALUE"""),"YES") -> YES | P8: =IFERROR(__xludf.DUMMYFUNCTION("""COMPUTED_VALUE"""),"NO") -> NO | Q8: =IFERROR(__xludf.DUMMYFUNCTION("""COMPUTED_VALUE"""),"NO") -> NO | R8: =IFERROR(__xludf.DUMMYFUNCTION("""COMPUTED_VALUE"""),"37'") -> 37' | S8: =IFERROR(__xludf.DUMMYFUNCTION("""COMPUTED_VALUE"""),134.0) -> 134 | T8: =IFERROR(__xludf.DUMMYFUNCTION("""COMPUTED_VALUE"""),40.0) -> 40 | U8: =IFERROR(__xludf.DUMMYFUNCTION("""COMPUTED_VALUE"""),"upper mezzanine (41 St & 7 Ave) to 7 platform for service in both directions") -> upper mezzanine (41 St & 7 Ave) to 7 platform for service in both directions | V8: =IFERROR(__xludf.DUMMYFUNCTION("""COMPUTED_VALUE"""),"POINT (-73.98772 40.755516)") -> POINT (-73.98772 40.755516)
A9: =IFERROR(__xludf.DUMMYFUNCTION("""COMPUTED_VALUE"""),"34 St-Herald Sq") -> 34 St-Herald Sq | B9: =IFERROR(__xludf.DUMMYFUNCTION("""COMPUTED_VALUE"""),"Broadway Line") -> Broadway Line | C9: =IFERROR(__xludf.DUMMYFUNCTION("""COMPUTED_VALUE"""),"Manhattan") -> Manhattan | D9: =IFERROR(__xludf.DUMMYFUNCTION("""COMPUTED_VALUE"""),"Midtown") -> Midtown | E9: =IFERROR(__xludf.DUMMYFUNCTION("""COMPUTED_VALUE"""),6580.0) -> 6580 | F9: =IFERROR(__xludf.DUMMYFUNCTION("""COMPUTED_VALUE"""),2.5012549E7) -> 25012549 | G9: =IFERROR(__xludf.DUMMYFUNCTION("""COMPUTED_VALUE"""),3.0) -> 3 | H9: =IFERROR(__xludf.DUMMYFUNCTION("""COMPUTED_VALUE"""),"↗️") -> ↗️ | I9: =IFERROR(__xludf.DUMMYFUNCTION("""COMPUTED_VALUE"""),14960.0) -> 14960 | J9: =IFERROR(__xludf.DUMMYFUNCTION("""COMPUTED_VALUE"""),39044.0) -> 39044 | K9: =IFERROR(__xludf.DUMMYFUNCTION("""COMPUTED_VALUE"""),22.0) -> 22 | L9: =IFERROR(__xludf.DUMMYFUNCTION("""COMPUTED_VALUE"""),"YES") -> YES | M9: =IFERROR(__xludf.DUMMYFUNCTION("""COMPUTED_VALUE"""),"NYCT") -> NYCT | N9: =IFERROR(__xludf.DUMMYFUNCTION("""COMPUTED_VALUE"""),"FUJITEC") -> FUJITEC | O9: =IFERROR(__xludf.DUMMYFUNCTION("""COMPUTED_VALUE"""),"YES") -> YES | P9: =IFERROR(__xludf.DUMMYFUNCTION("""COMPUTED_VALUE"""),"NO") -> NO | Q9: =IFERROR(__xludf.DUMMYFUNCTION("""COMPUTED_VALUE"""),"NO") -> NO | R9: =IFERROR(__xludf.DUMMYFUNCTION("""COMPUTED_VALUE"""),"30'") -> 30' | S9: =IFERROR(__xludf.DUMMYFUNCTION("""COMPUTED_VALUE"""),110.0) -> 110 | T9: =IFERROR(__xludf.DUMMYFUNCTION("""COMPUTED_VALUE"""),24.0) -> 24 | U9: =IFERROR(__xludf.DUMMYFUNCTION("""COMPUTED_VALUE"""),"N/Q/R/W mezzanine to uptown B/D/F/M platform") -> N/Q/R/W mezzanine to uptown B/D/F/M platform | V9: =IFERROR(__xludf.DUMMYFUNCTION("""COMPUTED_VALUE"""),"POINT (-73.98773 40.749763)") -> POINT (-73.98773 40.749763)
A10: =IFERROR(__xludf.DUMMYFUNCTION("""COMPUTED_VALUE"""),"Broadway Junction") -> Broadway Junction | B10: =IFERROR(__xludf.DUMMYFUNCTION("""COMPUTED_VALUE"""),"Canarsie Line") -> Canarsie Line | C10: =IFERROR(__xludf.DUMMYFUNCTION("""COMPUTED_VALUE"""),"Brooklyn") -> Brooklyn | D10: =IFERROR(__xludf.DUMMYFUNCTION("""COMPUTED_VALUE"""),"East New York") -> East New York | E10: =IFERROR(__xludf.DUMMYFUNCTION("""COMPUTED_VALUE"""),10423.0) -> 10423 | F10: =IFERROR(__xludf.DUMMYFUNCTION("""COMPUTED_VALUE"""),1808472.0) -> 1808472 | G10: =IFERROR(__xludf.DUMMYFUNCTION("""COMPUTED_VALUE"""),176.0) -> 176 | H10: =IFERROR(__xludf.DUMMYFUNCTION("""COMPUTED_VALUE"""),"↗️") -> ↗️ | I10: =IFERROR(__xludf.DUMMYFUNCTION("""COMPUTED_VALUE"""),17715.0) -> 17715 | J10: =IFERROR(__xludf.DUMMYFUNCTION("""COMPUTED_VALUE"""),35384.0) -> 35384 | K10: =IFERROR(__xludf.DUMMYFUNCTION("""COMPUTED_VALUE"""),22.0) -> 22 | L10: =IFERROR(__xludf.DUMMYFUNCTION("""COMPUTED_VALUE"""),"YES") -> YES | M10: =IFERROR(__xludf.DUMMYFUNCTION("""COMPUTED_VALUE"""),"NYCT") -> NYCT | N10: =IFERROR(__xludf.DUMMYFUNCTION("""COMPUTED_VALUE"""),"OK") -> OK | O10: =IFERROR(__xludf.DUMMYFUNCTION("""COMPUTED_VALUE"""),"YES") -> YES | P10: =IFERROR(__xludf.DUMMYFUNCTION("""COMPUTED_VALUE"""),"YES") -> YES | Q10: =IFERROR(__xludf.DUMMYFUNCTION("""COMPUTED_VALUE"""),"NO") -> NO | R10: =IFERROR(__xludf.DUMMYFUNCTION("""COMPUTED_VALUE"""),"44'") -> 44' | S10: =IFERROR(__xludf.DUMMYFUNCTION("""COMPUTED_VALUE"""),153.0) -> 153 | T10: =IFERROR(__xludf.DUMMYFUNCTION("""COMPUTED_VALUE"""),32.0) -> 32 | U10: =IFERROR(__xludf.DUMMYFUNCTION("""COMPUTED_VALUE"""),"A/C mezzanine (Van Sinderen Ave) to upper mezzanine for J/Z and L service") -> A/C mezzanine (Van Sinderen Ave) to upper mezzanine for J/Z and L service | V10: =IFERROR(__xludf.DUMMYFUNCTION("""COMPUTED_VALUE"""),"POINT (-73.90394 40.678566)") -> POINT (-73.90394 40.678566)
A11: =IFERROR(__xludf.DUMMYFUNCTION("""COMPUTED_VALUE"""),"Jamaica Van Wyck") -> Jamaica Van Wyck | B11: =IFERROR(__xludf.DUMMYFUNCTION("""COMPUTED_VALUE"""),"") | C11: =IFERROR(__xludf.DUMMYFUNCTION("""COMPUTED_VALUE"""),"") | D11: =IFERROR(__xludf.DUMMYFUNCTION("""COMPUTED_VALUE"""),"") | E11: =IFERROR(__xludf.DUMMYFUNCTION("""COMPUTED_VALUE"""),"") | F11: =IFERROR(__xludf.DUMMYFUNCTION("""COMPUTED_VALUE"""),"") | G11: =IFERROR(__xludf.DUMMYFUNCTION("""COMPUTED_VALUE"""),"") | H11: =IFERROR(__xludf.DUMMYFUNCTION("""COMPUTED_VALUE"""),"↗️") -> ↗️ | I11: =IFERROR(__xludf.DUMMYFUNCTION("""COMPUTED_VALUE"""),32478.0) -> 32478 | J11: =IFERROR(__xludf.DUMMYFUNCTION("""COMPUTED_VALUE"""),39584.0) -> 39584 | K11: =IFERROR(__xludf.DUMMYFUNCTION("""COMPUTED_VALUE"""),22.0) -> 22 | L11: =IFERROR(__xludf.DUMMYFUNCTION("""COMPUTED_VALUE"""),"YES") -> YES | M11: =IFERROR(__xludf.DUMMYFUNCTION("""COMPUTED_VALUE"""),"NYCT") -> NYCT | N11: =IFERROR(__xludf.DUMMYFUNCTION("""COMPUTED_VALUE"""),"KONE") -> KONE | O11: =IFERROR(__xludf.DUMMYFUNCTION("""COMPUTED_VALUE"""),"YES") -> YES | P11: =IFERROR(__xludf.DUMMYFUNCTION("""COMPUTED_VALUE"""),"YES") -> YES | Q11: =IFERROR(__xludf.DUMMYFUNCTION("""COMPUTED_VALUE"""),"YES") -> YES | R11: =IFERROR(__xludf.DUMMYFUNCTION("""COMPUTED_VALUE"""),"28'") -> 28' | S11: =IFERROR(__xludf.DUMMYFUNCTION("""COMPUTED_VALUE"""),106.0) -> 106 | T11: =IFERROR(__xludf.DUMMYFUNCTION("""COMPUTED_VALUE"""),"32in") -> 32in | U11: =IFERROR(__xludf.DUMMYFUNCTION("""COMPUTED_VALUE"""),"mezzanine to 89 Ave & Van Wyck Expressway (SW corner)") -> mezzanine to 89 Ave & Van Wyck Expressway (SW corner) | V11: =IFERROR(__xludf.DUMMYFUNCTION("""COMPUTED_VALUE"""),"POINT (-73.8164 40.70101)") -> POINT (-73.8164 40.70101)
A12: =IFERROR(__xludf.DUMMYFUNCTION("""COMPUTED_VALUE"""),"72 St") -> 72 St | B12: =IFERROR(__xludf.DUMMYFUNCTION("""COMPUTED_VALUE"""),"Broadway-7 Av Line") -> Broadway-7 Av Line | C12: =IFERROR(__xludf.DUMMYFUNCTION("""COMPUTED_VALUE"""),"Manhattan") -> Manhattan | D12: =IFERROR(__xludf.DUMMYFUNCTION("""COMPUTED_VALUE"""),"Upper West Side") -> Upper West Side | E12: =IFERROR(__xludf.DUMMYFUNCTION("""COMPUTED_VALUE"""),1762.0) -> 1762 | F12: =IFERROR(__xludf.DUMMYFUNCTION("""COMPUTED_VALUE"""),9752193.0) -> 9752193 | G12: =IFERROR(__xludf.DUMMYFUNCTION("""COMPUTED_VALUE"""),22.0) -> 22 | H12: =IFERROR(__xludf.DUMMYFUNCTION("""COMPUTED_VALUE"""),"↗️") -> ↗️ | I12: =IFERROR(__xludf.DUMMYFUNCTION("""COMPUTED_VALUE"""),42736.0) -> 42736 | J12: =IFERROR(__xludf.DUMMYFUNCTION("""COMPUTED_VALUE"""),42736.0) -> 42736 | K12: =IFERROR(__xludf.DUMMYFUNCTION("""COMPUTED_VALUE"""),22.0) -> 22 | L12: =IFERROR(__xludf.DUMMYFUNCTION("""COMPUTED_VALUE"""),"YES") -> YES | M12: =IFERROR(__xludf.DUMMYFUNCTION("""COMPUTED_VALUE"""),"NYCT") -> NYCT | N12: =IFERROR(__xludf.DUMMYFUNCTION("""COMPUTED_VALUE"""),"SCHINDLER") -> SCHINDLER | O12: =IFERROR(__xludf.DUMMYFUNCTION("""COMPUTED_VALUE"""),"YES") -> YES | P12: =IFERROR(__xludf.DUMMYFUNCTION("""COMPUTED_VALUE"""),"NO") -> NO | Q12: =IFERROR(__xludf.DUMMYFUNCTION("""COMPUTED_VALUE"""),"NO") -> NO | R12: =IFERROR(__xludf.DUMMYFUNCTION("""COMPUTED_VALUE"""),"20828 mm (68'4in)") -> 20828 mm (68'4in) | S12: =IFERROR(__xludf.DUMMYFUNCTION("""COMPUTED_VALUE"""),0.0) -> 0 | U12: =IFERROR(__xludf.DUMMYFUNCTION("""COMPUTED_VALUE"""),"69 St & 2nd Ave (NE corner) to upper mezzanine") -> 69 St & 2nd Ave (NE corner) to upper mezzanine | V12: =IFERROR(__xludf.DUMMYFUNCTION("""COMPUTED_VALUE"""),"POINT (-73.95921 40.76722)") -> POINT (-73.95921 40.76722)
A13: =IFERROR(__xludf.DUMMYFUNCTION("""COMPUTED_VALUE"""),"Sutphin Blvd-Archer Av-JFK Airport") -> Sutphin Blvd-Archer Av-JFK Airport | B13: =IFERROR(__xludf.DUMMYFUNCTION("""COMPUTED_VALUE"""),"Archer Av Line") -> Archer Av Line | C13: =IFERROR(__xludf.DUMMYFUNCTION("""COMPUTED_VALUE"""),"Queens") -> Queens | D13: =IFERROR(__xludf.DUMMYFUNCTION("""COMPUTED_VALUE"""),"Jamaica") -> Jamaica | E13: =IFERROR(__xludf.DUMMYFUNCTION("""COMPUTED_VALUE"""),32488.0) -> 32488 | F13: =IFERROR(__xludf.DUMMYFUNCTION("""COMPUTED_VALUE"""),6496357.0) -> 6496357 | G13: =IFERROR(__xludf.DUMMYFUNCTION("""COMPUTED_VALUE"""),32.0) -> 32 | H13: =IFERROR(__xludf.DUMMYFUNCTION("""COMPUTED_VALUE"""),"↗️") -> ↗️ | J13: =IFERROR(__xludf.DUMMYFUNCTION("""COMPUTED_VALUE"""),40760.0) -> 40760 | K13: =IFERROR(__xludf.DUMMYFUNCTION("""COMPUTED_VALUE"""),22.0) -> 22 | L13: =IFERROR(__xludf.DUMMYFUNCTION("""COMPUTED_VALUE"""),"NO") -> NO | M13: =IFERROR(__xludf.DUMMYFUNCTION("""COMPUTED_VALUE"""),"Private Contractor") -> Private Contractor | N13: =IFERROR(__xludf.DUMMYFUNCTION("""COMPUTED_VALUE"""),"KONE") -> KONE | O13: =IFERROR(__xludf.DUMMYFUNCTION("""COMPUTED_VALUE"""),"YES") -> YES | P13: =IFERROR(__xludf.DUMMYFUNCTION("""COMPUTED_VALUE"""),"NO") -> NO | Q13: =IFERROR(__xludf.DUMMYFUNCTION("""COMPUTED_VALUE"""),"NO") -> NO | U13: =IFERROR(__xludf.DUMMYFUNCTION("""COMPUTED_VALUE"""),"mezzanine to Sutphin Blvd & Archer Ave (SW corner) for connection to LIRR and AirTrain") -> mezzanine to Sutphin Blvd & Archer Ave (SW corner) for connection to LIRR and AirTrain | V13: =IFERROR(__xludf.DUMMYFUNCTION("""COMPUTED_VALUE"""),"POINT (-73.80781 40.700127)") -> POINT (-73.80781 40.700127)
A14: =IFERROR(__xludf.DUMMYFUNCTION("""COMPUTED_VALUE"""),"5 Av/53 St") -> 5 Av/53 St | B14: =IFERROR(__xludf.DUMMYFUNCTION("""COMPUTED_VALUE"""),"Queens Blvd Line") -> Queens Blvd Line | C14: =IFERROR(__xludf.DUMMYFUNCTION("""COMPUTED_VALUE"""),"Manhattan") -> Manhattan | D14: =IFERROR(__xludf.DUMMYFUNCTION("""COMPUTED_VALUE"""),"Midtown") -> Midtown | E14: =IFERROR(__xludf.DUMMYFUNCTION("""COMPUTED_VALUE"""),12359.0) -> 12359 | F14: =IFERROR(__xludf.DUMMYFUNCTION("""COMPUTED_VALUE"""),4590651.0) -> 4590651 | G14: =IFERROR(__xludf.DUMMYFUNCTION("""COMPUTED_VALUE"""),64.0) -> 64 | H14: =IFERROR(__xludf.DUMMYFUNCTION("""COMPUTED_VALUE"""),"↗️") -> ↗️ | I14: =IFERROR(__xludf.DUMMYFUNCTION("""COMPUTED_VALUE"""),22087.0) -> 22087 | J14: =IFERROR(__xludf.DUMMYFUNCTION("""COMPUTED_VALUE"""),46000.0) -> 46000 | K14: =IFERROR(__xludf.DUMMYFUNCTION("""COMPUTED_VALUE"""),22.0) -> 22 | L14: =IFERROR(__xludf.DUMMYFUNCTION("""COMPUTED_VALUE"""),"YES") -> YES | M14: =IFERROR(__xludf.DUMMYFUNCTION("""COMPUTED_VALUE"""),"NYCT") -> NYCT | N14: =IFERROR(__xludf.DUMMYFUNCTION("""COMPUTED_VALUE"""),"KONE") -> KONE | O14: =IFERROR(__xludf.DUMMYFUNCTION("""COMPUTED_VALUE"""),"YES") -> YES | P14: =IFERROR(__xludf.DUMMYFUNCTION("""COMPUTED_VALUE"""),"NO") -> NO | Q14: =IFERROR(__xludf.DUMMYFUNCTION("""COMPUTED_VALUE"""),"NO") -> NO | R14: =IFERROR(__xludf.DUMMYFUNCTION("""COMPUTED_VALUE"""),"48'") -> 48' | S14: =IFERROR(__xludf.DUMMYFUNCTION("""COMPUTED_VALUE"""),166.0) -> 166 | T14: =IFERROR(__xludf.DUMMYFUNCTION("""COMPUTED_VALUE"""),40.0) -> 40 | U14: =IFERROR(__xludf.DUMMYFUNCTION("""COMPUTED_VALUE"""),"downtown platform to mezzanine for 5th Ave & 53 St exit") -> downtown platform to mezzanine for 5th Ave & 53 St exit | V14: =IFERROR(__xludf.DUMMYFUNCTION("""COMPUTED_VALUE"""),"POINT (-73.97628 40.76059)") -> POINT (-73.97628 40.76059)
A15: =IFERROR(__xludf.DUMMYFUNCTION("""COMPUTED_VALUE"""),"Lexington Av/53 St") -> Lexington Av/53 St | B15: =IFERROR(__xludf.DUMMYFUNCTION("""COMPUTED_VALUE"""),"") | C15: =IFERROR(__xludf.DUMMYFUNCTION("""COMPUTED_VALUE"""),"") | D15: =IFERROR(__xludf.DUMMYFUNCTION("""COMPUTED_VALUE"""),"") | E15: =IFERROR(__xludf.DUMMYFUNCTION("""COMPUTED_VALUE"""),"") | F15: =IFERROR(__xludf.DUMMYFUNCTION("""COMPUTED_VALUE"""),"") | G15: =IFERROR(__xludf.DUMMYFUNCTION("""COMPUTED_VALUE"""),"") | H15: =IFERROR(__xludf.DUMMYFUNCTION("""COMPUTED_VALUE"""),"↗️") -> ↗️ | I15: =IFERROR(__xludf.DUMMYFUNCTION("""COMPUTED_VALUE"""),3.0) -> 3 | J15: =IFERROR(__xludf.DUMMYFUNCTION("""COMPUTED_VALUE"""),40700.0) -> 40700 | K15: =IFERROR(__xludf.DUMMYFUNCTION("""COMPUTED_VALUE"""),22.0) -> 22 | L15: =IFERROR(__xludf.DUMMYFUNCTION("""COMPUTED_VALUE"""),"NO") -> NO | M15: =IFERROR(__xludf.DUMMYFUNCTION("""COMPUTED_VALUE"""),"Private Contractor") -> Private Contractor | N15: =IFERROR(__xludf.DUMMYFUNCTION("""COMPUTED_VALUE"""),"AM") -> AM | O15: =IFERROR(__xludf.DUMMYFUNCTION("""COMPUTED_VALUE"""),"YES") -> YES | P15: =IFERROR(__xludf.DUMMYFUNCTION("""COMPUTED_VALUE"""),"NO") -> NO | Q15: =IFERROR(__xludf.DUMMYFUNCTION("""COMPUTED_VALUE"""),"NO") -> NO | U15: =IFERROR(__xludf.DUMMYFUNCTION("""COMPUTED_VALUE"""),"Downtown 6 underpass to mezzanine for E/F service and 52 St & Lexington Av exit.") -> Downtown 6 underpass to mezzanine for E/F service and 52 St & Lexington Av exit. | V15: =IFERROR(__xludf.DUMMYFUNCTION("""COMPUTED_VALUE"""),"POINT (-73.97133 40.757572)") -> POINT (-73.97133 40.757572)
A16: =IFERROR(__xludf.DUMMYFUNCTION("""COMPUTED_VALUE"""),"Pelham Pkwy") -> Pelham Pkwy | B16: =IFERROR(__xludf.DUMMYFUNCTION("""COMPUTED_VALUE"""),"White Plains Rd Line") -> White Plains Rd Line | C16: =IFERROR(__xludf.DUMMYFUNCTION("""COMPUTED_VALUE"""),"The Bronx") -> The Bronx | D16: =IFERROR(__xludf.DUMMYFUNCTION("""COMPUTED_VALUE"""),"Pelham Parkway") -> Pelham Parkway | E16: =IFERROR(__xludf.DUMMYFUNCTION("""COMPUTED_VALUE"""),6272.0) -> 6272 | F16: =IFERROR(__xludf.DUMMYFUNCTION("""COMPUTED_VALUE"""),1514724.0) -> 1514724 | G16: =IFERROR(__xludf.DUMMYFUNCTION("""COMPUTED_VALUE"""),212.0) -> 212 | H16: =IFERROR(__xludf.DUMMYFUNCTION("""COMPUTED_VALUE"""),"↗️") -> ↗️ | I16: =IFERROR(__xludf.DUMMYFUNCTION("""COMPUTED_VALUE"""),35405.0) -> 35405 | J16: =IFERROR(__xludf.DUMMYFUNCTION("""COMPUTED_VALUE"""),44987.0) -> 44987 | K16: =IFERROR(__xludf.DUMMYFUNCTION("""COMPUTED_VALUE"""),22.0) -> 22 | L16: =IFERROR(__xludf.DUMMYFUNCTION("""COMPUTED_VALUE"""),"YES") -> YES | M16: =IFERROR(__xludf.DUMMYFUNCTION("""COMPUTED_VALUE"""),"NYCT") -> NYCT | N16: =IFERROR(__xludf.DUMMYFUNCTION("""COMPUTED_VALUE"""),"KONE") -> KONE | O16: =IFERROR(__xludf.DUMMYFUNCTION("""COMPUTED_VALUE"""),"YES") -> YES | P16: =IFERROR(__xludf.DUMMYFUNCTION("""COMPUTED_VALUE"""),"NO") -> NO | Q16: =IFERROR(__xludf.DUMMYFUNCTION("""COMPUTED_VALUE"""),"YES") -> YES | R16: =IFERROR(__xludf.DUMMYFUNCTION("""COMPUTED_VALUE"""),"3518 mm (11'-6 1/2in)") -> 3518 mm (11'-6 1/2in) | S16: =IFERROR(__xludf.DUMMYFUNCTION("""COMPUTED_VALUE"""),74.0) -> 74 | T16: =IFERROR(__xludf.DUMMYFUNCTION("""COMPUTED_VALUE"""),"1000mm (40in NOMINAL)") -> 1000mm (40in NOMINAL) | U16: =IFERROR(__xludf.DUMMYFUNCTION("""COMPUTED_VALUE"""),"mezzanine to Manhattan-bound platform") -> mezzanine to Manhattan-bound platform | V16: =IFERROR(__xludf.DUMMYFUNCTION("""COMPUTED_VALUE"""),"POINT (-73.86772 40.856728)") -> POINT (-73.86772 40.856728)
A17: =IFERROR(__xludf.DUMMYFUNCTION("""COMPUTED_VALUE"""),"59 St-Columbus Circle") -> 59 St-Columbus Circle | B17: =IFERROR(__xludf.DUMMYFUNCTION("""COMPUTED_VALUE"""),"Broadway-7 Av Line") -> Broadway-7 Av Line | C17: =IFERROR(__xludf.DUMMYFUNCTION("""COMPUTED_VALUE"""),"Manhattan") -> Manhattan | D17: =IFERROR(__xludf.DUMMYFUNCTION("""COMPUTED_VALUE"""),"Midtown") -> Midtown | E17: =IFERROR(__xludf.DUMMYFUNCTION("""COMPUTED_VALUE"""),1762.0) -> 1762 | F17: =IFERROR(__xludf.DUMMYFUNCTION("""COMPUTED_VALUE"""),1.6884912E7) -> 16884912 | G17: =IFERROR(__xludf.DUMMYFUNCTION("""COMPUTED_VALUE"""),7.0) -> 7 | H17: =IFERROR(__xludf.DUMMYFUNCTION("""COMPUTED_VALUE"""),"↗️") -> ↗️ | I17: =IFERROR(__xludf.DUMMYFUNCTION("""COMPUTED_VALUE"""),3.0) -> 3 | J17: =IFERROR(__xludf.DUMMYFUNCTION("""COMPUTED_VALUE"""),40664.0) -> 40664 | K17: =IFERROR(__xludf.DUMMYFUNCTION("""COMPUTED_VALUE"""),22.0) -> 22 | L17: =IFERROR(__xludf.DUMMYFUNCTION("""COMPUTED_VALUE"""),"NO") -> NO | M17: =IFERROR(__xludf.DUMMYFUNCTION("""COMPUTED_VALUE"""),"Private Contractor") -> Private Contractor | N17: =IFERROR(__xludf.DUMMYFUNCTION("""COMPUTED_VALUE"""),"OK") -> OK | O17: =IFERROR(__xludf.DUMMYFUNCTION("""COMPUTED_VALUE"""),"YES") -> YES | P17: =IFERROR(__xludf.DUMMYFUNCTION("""COMPUTED_VALUE"""),"NO") -> NO | Q17: =IFERROR(__xludf.DUMMYFUNCTION("""COMPUTED_VALUE"""),"NO") -> NO | S17: =IFERROR(__xludf.DUMMYFUNCTION("""COMPUTED_VALUE"""),0.0) -> 0 | U17: =IFERROR(__xludf.DUMMYFUNCTION("""COMPUTED_VALUE"""),"A/B/C/D mezzanine to 8th Ave & 58 St (NW corner)") -> A/B/C/D mezzanine to 8th Ave & 58 St (NW corner) | V17: =IFERROR(__xludf.DUMMYFUNCTION("""COMPUTED_VALUE"""),"POINT (-73.98249 40.767677)") -> POINT (-73.98249 40.767677)
A18: =IFERROR(__xludf.DUMMYFUNCTION("""COMPUTED_VALUE"""),"Roosevelt Island") -> Roosevelt Island | B18: =IFERROR(__xludf.DUMMYFUNCTION("""COMPUTED_VALUE"""),"63rd St Line") -> 63rd St Line | C18: =IFERROR(__xludf.DUMMYFUNCTION("""COMPUTED_VALUE"""),"Manhattan") -> Manhattan | D18: =IFERROR(__xludf.DUMMYFUNCTION("""COMPUTED_VALUE"""),"Roosevelt Island") -> Roosevelt Island | E18: =IFERROR(__xludf.DUMMYFUNCTION("""COMPUTED_VALUE"""),32810.0) -> 32810 | F18: =IFERROR(__xludf.DUMMYFUNCTION("""COMPUTED_VALUE"""),1885823.0) -> 1885823 | G18: =IFERROR(__xludf.DUMMYFUNCTION("""COMPUTED_VALUE"""),171.0) -> 171 | H18: =IFERROR(__xludf.DUMMYFUNCTION("""COMPUTED_VALUE"""),"↗️") -> ↗️ | I18: =IFERROR(__xludf.DUMMYFUNCTION("""COMPUTED_VALUE"""),32782.0) -> 32782 | J18: =IFERROR(__xludf.DUMMYFUNCTION("""COMPUTED_VALUE"""),39647.0) -> 39647 | K18: =IFERROR(__xludf.DUMMYFUNCTION("""COMPUTED_VALUE"""),22.0) -> 22 | L18: =IFERROR(__xludf.DUMMYFUNCTION("""COMPUTED_VALUE"""),"YES") -> YES | M18: =IFERROR(__xludf.DUMMYFUNCTION("""COMPUTED_VALUE"""),"NYCT") -> NYCT | N18: =IFERROR(__xludf.DUMMYFUNCTION("""COMPUTED_VALUE"""),"KONE") -> KONE | O18: =IFERROR(__xludf.DUMMYFUNCTION("""COMPUTED_VALUE"""),"YES") -> YES | P18: =IFERROR(__xludf.DUMMYFUNCTION("""COMPUTED_VALUE"""),"NO") -> NO | Q18: =IFERROR(__xludf.DUMMYFUNCTION("""COMPUTED_VALUE"""),"NO") -> NO | R18: =IFERROR(__xludf.DUMMYFUNCTION("""COMPUTED_VALUE"""),"14'") -> 14' | S18: =IFERROR(__xludf.DUMMYFUNCTION("""COMPUTED_VALUE"""),56.0) -> 56 | T18: =IFERROR(__xludf.DUMMYFUNCTION("""COMPUTED_VALUE"""),40.0) -> 40 | U18: =IFERROR(__xludf.DUMMYFUNCTION("""COMPUTED_VALUE"""),"Manhattan-bound platform to lower mezzanine") -> Manhattan-bound platform to lower mezzanine | V18: =IFERROR(__xludf.DUMMYFUNCTION("""COMPUTED_VALUE"""),"POINT (-73.952354 40.75876)") -> POINT (-73.952354 40.75876)
A19: =IFERROR(__xludf.DUMMYFUNCTION("""COMPUTED_VALUE"""),"Bowling Green") -> Bowling Green | B19: =IFERROR(__xludf.DUMMYFUNCTION("""COMPUTED_VALUE"""),"Lexington Av Line") -> Lexington Av Line | C19: =IFERROR(__xludf.DUMMYFUNCTION("""COMPUTED_VALUE"""),"Manhattan") -> Manhattan | D19: =IFERROR(__xludf.DUMMYFUNCTION("""COMPUTED_VALUE"""),"Financial District") -> Financial District | E19: =IFERROR(__xludf.DUMMYFUNCTION("""COMPUTED_VALUE"""),2018.0) -> 2018 | F19: =IFERROR(__xludf.DUMMYFUNCTION("""COMPUTED_VALUE"""),4676646.0) -> 4676646 | G19: =IFERROR(__xludf.DUMMYFUNCTION("""COMPUTED_VALUE"""),62.0) -> 62 | H19: =IFERROR(__xludf.DUMMYFUNCTION("""COMPUTED_VALUE"""),"↗️") -> ↗️ | I19: =IFERROR(__xludf.DUMMYFUNCTION("""COMPUTED_VALUE"""),28216.0) -> 28216 | J19: =IFERROR(__xludf.DUMMYFUNCTION("""COMPUTED_VALUE"""),38430.0) -> 38430 | K19: =IFERROR(__xludf.DUMMYFUNCTION("""COMPUTED_VALUE"""),22.0) -> 22 | L19: =IFERROR(__xludf.DUMMYFUNCTION("""COMPUTED_VALUE"""),"YES") -> YES | M19: =IFERROR(__xludf.DUMMYFUNCTION("""COMPUTED_VALUE"""),"NYCT") -> NYCT | N19: =IFERROR(__xludf.DUMMYFUNCTION("""COMPUTED_VALUE"""),"FUJITEC") -> FUJITEC | O19: =IFERROR(__xludf.DUMMYFUNCTION("""COMPUTED_VALUE"""),"YES") -> YES | P19: =IFERROR(__xludf.DUMMYFUNCTION("""COMPUTED_VALUE"""),"NO") -> NO | Q19: =IFERROR(__xludf.DUMMYFUNCTION("""COMPUTED_VALUE"""),"NO") -> NO | R19: =IFERROR(__xludf.DUMMYFUNCTION("""COMPUTED_VALUE"""),"23'") -> 23' | S19: =IFERROR(__xludf.DUMMYFUNCTION("""COMPUTED_VALUE"""),92.0) -> 92 | T19: =IFERROR(__xludf.DUMMYFUNCTION("""COMPUTED_VALUE"""),40.0) -> 40 | U19: =IFERROR(__xludf.DUMMYFUNCTION("""COMPUTED_VALUE"""),"lower mezzanine to uptown 4/5 platform") -> lower mezzanine to uptown 4/5 platform | V19: =IFERROR(__xludf.DUMMYFUNCTION("""COMPUTED_VALUE"""),"POINT (-74.01387 40.704838)") -> POINT (-74.01387 40.704838)
A20: =IFERROR(__xludf.DUMMYFUNCTION("""COMPUTED_VALUE"""),"72 St") -> 72 St | B20: =IFERROR(__xludf.DUMMYFUNCTION("""COMPUTED_VALUE"""),"Broadway-7 Av Line") -> Broadway-7 Av Line | C20: =IFERROR(__xludf.DUMMYFUNCTION("""COMPUTED_VALUE"""),"Manhattan") -> Manhattan | D20: =IFERROR(__xludf.DUMMYFUNCTION("""COMPUTED_VALUE"""),"Upper West Side") -> Upper West Side | E20: =IFERROR(__xludf.DUMMYFUNCTION("""COMPUTED_VALUE"""),1762.0) -> 1762 | F20: =IFERROR(__xludf.DUMMYFUNCTION("""COMPUTED_VALUE"""),9752193.0) -> 9752193 | G20: =IFERROR(__xludf.DUMMYFUNCTION("""COMPUTED_VALUE"""),22.0) -> 22 | H20: =IFERROR(__xludf.DUMMYFUNCTION("""COMPUTED_VALUE"""),"↗️") -> ↗️ | I20: =IFERROR(__xludf.DUMMYFUNCTION("""COMPUTED_VALUE"""),42736.0) -> 42736 | J20: =IFERROR(__xludf.DUMMYFUNCTION("""COMPUTED_VALUE"""),42736.0) -> 42736 | K20: =IFERROR(__xludf.DUMMYFUNCTION("""COMPUTED_VALUE"""),22.0) -> 22 | L20: =IFERROR(__xludf.DUMMYFUNCTION("""COMPUTED_VALUE"""),"YES") -> YES | M20: =IFERROR(__xludf.DUMMYFUNCTION("""COMPUTED_VALUE"""),"NYCT") -> NYCT | N20: =IFERROR(__xludf.DUMMYFUNCTION("""COMPUTED_VALUE"""),"SCHINDLER") -> SCHINDLER | O20: =IFERROR(__xludf.DUMMYFUNCTION("""COMPUTED_VALUE"""),"YES") -> YES | P20: =IFERROR(__xludf.DUMMYFUNCTION("""COMPUTED_VALUE"""),"YES") -> YES | Q20: =IFERROR(__xludf.DUMMYFUNCTION("""COMPUTED_VALUE"""),"YES") -> YES | R20: =IFERROR(__xludf.DUMMYFUNCTION("""COMPUTED_VALUE"""),"21577 mm (70' 9 1/2in)") -> 21577 mm (70' 9 1/2in) | S20: =IFERROR(__xludf.DUMMYFUNCTION("""COMPUTED_VALUE"""),0.0) -> 0 | U20: =IFERROR(__xludf.DUMMYFUNCTION("""COMPUTED_VALUE"""),"lower mezzanine to 72 St & 2nd Ave (NW corner)") -> lower mezzanine to 72 St & 2nd Ave (NW corner) | V20: =IFERROR(__xludf.DUMMYFUNCTION("""COMPUTED_VALUE"""),"POINT (-73.95847 40.76906)") -> POINT (-73.95847 40.76906)
A21: =IFERROR(__xludf.DUMMYFUNCTION("""COMPUTED_VALUE"""),"181 St") -> 181 St | B21: =IFERROR(__xludf.DUMMYFUNCTION("""COMPUTED_VALUE"""),"8 Av Line") -> 8 Av Line | C21: =IFERROR(__xludf.DUMMYFUNCTION("""COMPUTED_VALUE"""),"Manhattan") -> Manhattan | D21: =IFERROR(__xludf.DUMMYFUNCTION("""COMPUTED_VALUE"""),"Washington Heights") -> Washington Heights | E21: =IFERROR(__xludf.DUMMYFUNCTION("""COMPUTED_VALUE"""),11942.0) -> 11942 | F21: =IFERROR(__xludf.DUMMYFUNCTION("""COMPUTED_VALUE"""),2042771.0) -> 2042771 | G21: =IFERROR(__xludf.DUMMYFUNCTION("""COMPUTED_VALUE"""),160.0) -> 160 | H21: =IFERROR(__xludf.DUMMYFUNCTION("""COMPUTED_VALUE"""),"↗️") -> ↗️ | I21: =IFERROR(__xludf.DUMMYFUNCTION("""COMPUTED_VALUE"""),35517.0) -> 35517 | J21: =IFERROR(__xludf.DUMMYFUNCTION("""COMPUTED_VALUE"""),45016.0) -> 45016 | K21: =IFERROR(__xludf.DUMMYFUNCTION("""COMPUTED_VALUE"""),22.0) -> 22 | L21: =IFERROR(__xludf.DUMMYFUNCTION("""COMPUTED_VALUE"""),"YES") -> YES | M21: =IFERROR(__xludf.DUMMYFUNCTION("""COMPUTED_VALUE"""),"NYCT") -> NYCT | N21: =IFERROR(__xludf.DUMMYFUNCTION("""COMPUTED_VALUE"""),"KONE") -> KONE | O21: =IFERROR(__xludf.DUMMYFUNCTION("""COMPUTED_VALUE"""),"YES") -> YES | P21: =IFERROR(__xludf.DUMMYFUNCTION("""COMPUTED_VALUE"""),"NO") -> NO | Q21: =IFERROR(__xludf.DUMMYFUNCTION("""COMPUTED_VALUE"""),"NO") -> NO | R21: =IFERROR(__xludf.DUMMYFUNCTION("""COMPUTED_VALUE"""),"15824 mm (51'-11in)") -> 15824 mm (51'-11in) | S21: =IFERROR(__xludf.DUMMYFUNCTION("""COMPUTED_VALUE"""),112.0) -> 112 | T21: =IFERROR(__xludf.DUMMYFUNCTION("""COMPUTED_VALUE"""),"800 mm (32in NOMINAL)") -> 800 mm (32in NOMINAL) | U21: =IFERROR(__xludf.DUMMYFUNCTION("""COMPUTED_VALUE"""),"lower mezzanine to upper mezzanine for 181 St & Fort Washington Ave exit") -> lower mezzanine to upper mezzanine for 181 St & Fort Washington Ave exit | V21: =IFERROR(__xludf.DUMMYFUNCTION("""COMPUTED_VALUE"""),"POINT (-73.938095 40.851116)") -> POINT (-73.938095 40.851116)
A22: =IFERROR(__xludf.DUMMYFUNCTION("""COMPUTED_VALUE"""),"34 St-Hudson Yards") -> 34 St-Hudson Yards | B22: =IFERROR(__xludf.DUMMYFUNCTION("""COMPUTED_VALUE"""),"Flushing Line") -> Flushing Line | C22: =IFERROR(__xludf.DUMMYFUNCTION("""COMPUTED_VALUE"""),"Manhattan") -> Manhattan | D22: =IFERROR(__xludf.DUMMYFUNCTION("""COMPUTED_VALUE"""),"Hell's Kitchen") -> Hell's Kitchen | E22: =IFERROR(__xludf.DUMMYFUNCTION("""COMPUTED_VALUE"""),42260.0) -> 42260 | F22: =IFERROR(__xludf.DUMMYFUNCTION("""COMPUTED_VALUE"""),6082370.0) -> 6082370 | G22: =IFERROR(__xludf.DUMMYFUNCTION("""COMPUTED_VALUE"""),39.0) -> 39 | H22: =IFERROR(__xludf.DUMMYFUNCTION("""COMPUTED_VALUE"""),"↗️") -> ↗️ | I22: =IFERROR(__xludf.DUMMYFUNCTION("""COMPUTED_VALUE"""),43343.0) -> 43343 | J22: =IFERROR(__xludf.DUMMYFUNCTION("""COMPUTED_VALUE"""),43343.0) -> 43343 | K22: =IFERROR(__xludf.DUMMYFUNCTION("""COMPUTED_VALUE"""),22.0) -> 22 | L22: =IFERROR(__xludf.DUMMYFUNCTION("""COMPUTED_VALUE"""),"YES") -> YES | M22: =IFERROR(__xludf.DUMMYFUNCTION("""COMPUTED_VALUE"""),"NYCT") -> NYCT | N22: =IFERROR(__xludf.DUMMYFUNCTION("""COMPUTED_VALUE"""),"SCHINDLER") -> SCHINDLER | O22: =IFERROR(__xludf.DUMMYFUNCTION("""COMPUTED_VALUE"""),"YES") -> YES | P22: =IFERROR(__xludf.DUMMYFUNCTION("""COMPUTED_VALUE"""),"NO") -> NO | Q22: =IFERROR(__xludf.DUMMYFUNCTION("""COMPUTED_VALUE"""),"NO") -> NO | R22: =IFERROR(__xludf.DUMMYFUNCTION("""COMPUTED_VALUE"""),"24'") -> 24' | S22: =IFERROR(__xludf.DUMMYFUNCTION("""COMPUTED_VALUE"""),90.0) -> 90 | T22: =IFERROR(__xludf.DUMMYFUNCTION("""COMPUTED_VALUE"""),40.0) -> 40 | U22: =IFERROR(__xludf.DUMMYFUNCTION("""COMPUTED_VALUE"""),"lower mezzanine to upper mezzanine for Hudson Blvd E & 35 St exit") -> lower mezzanine to upper mezzanine for Hudson Blvd E & 35 St exit | V22: =IFERROR(__xludf.DUMMYFUNCTION("""COMPUTED_VALUE"""),"POINT (-74.00111 40.75609)") -> POINT (-74.00111 40.75609)
A23: =IFERROR(__xludf.DUMMYFUNCTION("""COMPUTED_VALUE"""),"Jamaica Center-Parsons/Archer") -> Jamaica Center-Parsons/Archer | B23: =IFERROR(__xludf.DUMMYFUNCTION("""COMPUTED_VALUE"""),"Archer Av Line") -> Archer Av Line | C23: =IFERROR(__xludf.DUMMYFUNCTION("""COMPUTED_VALUE"""),"Queens") -> Queens | D23: =IFERROR(__xludf.DUMMYFUNCTION("""COMPUTED_VALUE"""),"Jamaica") -> Jamaica | E23: =IFERROR(__xludf.DUMMYFUNCTION("""COMPUTED_VALUE"""),32488.0) -> 32488 | F23: =IFERROR(__xludf.DUMMYFUNCTION("""COMPUTED_VALUE"""),6137267.0) -> 6137267 | G23: =IFERROR(__xludf.DUMMYFUNCTION("""COMPUTED_VALUE"""),38.0) -> 38 | H23: =IFERROR(__xludf.DUMMYFUNCTION("""COMPUTED_VALUE"""),"↗️") -> ↗️ | I23: =IFERROR(__xludf.DUMMYFUNCTION("""COMPUTED_VALUE"""),32478.0) -> 32478 | J23: =IFERROR(__xludf.DUMMYFUNCTION("""COMPUTED_VALUE"""),39420.0) -> 39420 | K23: =IFERROR(__xludf.DUMMYFUNCTION("""COMPUTED_VALUE"""),22.0) -> 22 | L23: =IFERROR(__xludf.DUMMYFUNCTION("""COMPUTED_VALUE"""),"YES") -> YES | M23: =IFERROR(__xludf.DUMMYFUNCTION("""COMPUTED_VALUE"""),"NYCT") -> NYCT | N23: =IFERROR(__xludf.DUMMYFUNCTION("""COMPUTED_VALUE"""),"KONE") -> KONE | O23: =IFERROR(__xludf.DUMMYFUNCTION("""COMPUTED_VALUE"""),"YES") -> YES | P23: =IFERROR(__xludf.DUMMYFUNCTION("""COMPUTED_VALUE"""),"NO") -> NO | Q23: =IFERROR(__xludf.DUMMYFUNCTION("""COMPUTED_VALUE"""),"NO") -> NO | R23: =IFERROR(__xludf.DUMMYFUNCTION("""COMPUTED_VALUE"""),"28'") -> 28' | S23: =IFERROR(__xludf.DUMMYFUNCTION("""COMPUTED_VALUE"""),106.0) -> 106 | T23: =IFERROR(__xludf.DUMMYFUNCTION("""COMPUTED_VALUE"""),"32in") -> 32in | U23: =IFERROR(__xludf.DUMMYFUNCTION("""COMPUTED_VALUE"""),"mezzanine (153 St & Archer Ave) to J/Z platform for Brooklyn-bound service") -> mezzanine (153 St & Archer Ave) to J/Z platform for Brooklyn-bound service | V23: =IFERROR(__xludf.DUMMYFUNCTION("""COMPUTED_VALUE"""),"POINT (-73.801926 40.70198)") -> POINT (-73.801926 40.70198)
A24: =IFERROR(__xludf.DUMMYFUNCTION("""COMPUTED_VALUE"""),"14 St-Union Sq") -> 14 St-Union Sq | B24: =IFERROR(__xludf.DUMMYFUNCTION("""COMPUTED_VALUE"""),"Broadway Line") -> Broadway Line | C24: =IFERROR(__xludf.DUMMYFUNCTION("""COMPUTED_VALUE"""),"Manhattan") -> Manhattan | D24: =IFERROR(__xludf.DUMMYFUNCTION("""COMPUTED_VALUE"""),"Union Square") -> Union Square | E24: =IFERROR(__xludf.DUMMYFUNCTION("""COMPUTED_VALUE"""),6457.0) -> 6457 | F24: =IFERROR(__xludf.DUMMYFUNCTION("""COMPUTED_VALUE"""),2.2811597E7) -> 22811597 | G24: =IFERROR(__xludf.DUMMYFUNCTION("""COMPUTED_VALUE"""),4.0) -> 4 | H24: =IFERROR(__xludf.DUMMYFUNCTION("""COMPUTED_VALUE"""),"↗️") -> ↗️ | J24: =IFERROR(__xludf.DUMMYFUNCTION("""COMPUTED_VALUE"""),41071.0) -> 41071 | K24: =IFERROR(__xludf.DUMMYFUNCTION("""COMPUTED_VALUE"""),22.0) -> 22 | L24: =IFERROR(__xludf.DUMMYFUNCTION("""COMPUTED_VALUE"""),"NO") -> NO | M24: =IFERROR(__xludf.DUMMYFUNCTION("""COMPUTED_VALUE"""),"Private Contractor") -> Private Contractor | N24: =IFERROR(__xludf.DUMMYFUNCTION("""COMPUTED_VALUE"""),"AM") -> AM | O24: =IFERROR(__xludf.DUMMYFUNCTION("""COMPUTED_VALUE"""),"YES") -> YES | P24: =IFERROR(__xludf.DUMMYFUNCTION("""COMPUTED_VALUE"""),"NO") -> NO | Q24: =IFERROR(__xludf.DUMMYFUNCTION("""COMPUTED_VALUE"""),"NO") -> NO | U24: =IFERROR(__xludf.DUMMYFUNCTION("""COMPUTED_VALUE"""),"14 St & 4th Ave (NE corner) to mezzanine for 4/5/6/L service and access to N/Q/R/W") -> 14 St & 4th Ave (NE corner) to mezzanine for 4/5/6/L service and access to N/Q/R/W | V24: =IFERROR(__xludf.DUMMYFUNCTION("""COMPUTED_VALUE"""),"POINT (-73.98946 40.73445)") -> POINT (-73.98946 40.73445)
A25: =IFERROR(__xludf.DUMMYFUNCTION("""COMPUTED_VALUE"""),"34 St-Herald Sq") -> 34 St-Herald Sq | B25: =IFERROR(__xludf.DUMMYFUNCTION("""COMPUTED_VALUE"""),"Broadway Line") -> Broadway Line | C25: =IFERROR(__xludf.DUMMYFUNCTION("""COMPUTED_VALUE"""),"Manhattan") -> Manhattan | D25: =IFERROR(__xludf.DUMMYFUNCTION("""COMPUTED_VALUE"""),"Midtown") -> Midtown | E25: =IFERROR(__xludf.DUMMYFUNCTION("""COMPUTED_VALUE"""),6580.0) -> 6580 | F25: =IFERROR(__xludf.DUMMYFUNCTION("""COMPUTED_VALUE"""),2.5012549E7) -> 25012549 | G25: =IFERROR(__xludf.DUMMYFUNCTION("""COMPUTED_VALUE"""),3.0) -> 3 | H25: =IFERROR(__xludf.DUMMYFUNCTION("""COMPUTED_VALUE"""),"↗️") -> ↗️ | I25: =IFERROR(__xludf.DUMMYFUNCTION("""COMPUTED_VALUE"""),14960.0) -> 14960 | J25: =IFERROR(__xludf.DUMMYFUNCTION("""COMPUTED_VALUE"""),39044.0) -> 39044 | K25: =IFERROR(__xludf.DUMMYFUNCTION("""COMPUTED_VALUE"""),22.0) -> 22 | L25: =IFERROR(__xludf.DUMMYFUNCTION("""COMPUTED_VALUE"""),"YES") -> YES | M25: =IFERROR(__xludf.DUMMYFUNCTION("""COMPUTED_VALUE"""),"NYCT") -> NYCT | N25: =IFERROR(__xludf.DUMMYFUNCTION("""COMPUTED_VALUE"""),"FUJITEC") -> FUJITEC | O25: =IFERROR(__xludf.DUMMYFUNCTION("""COMPUTED_VALUE"""),"YES") -> YES | P25: =IFERROR(__xludf.DUMMYFUNCTION("""COMPUTED_VALUE"""),"NO") -> NO | Q25: =IFERROR(__xludf.DUMMYFUNCTION("""COMPUTED_VALUE"""),"NO") -> NO | R25: =IFERROR(__xludf.DUMMYFUNCTION("""COMPUTED_VALUE"""),"30'") -> 30' | S25: =IFERROR(__xludf.DUMMYFUNCTION("""COMPUTED_VALUE"""),109.0) -> 109 | T25: =IFERROR(__xludf.DUMMYFUNCTION("""COMPUTED_VALUE"""),24.0) -> 24 | U25: =IFERROR(__xludf.DUMMYFUNCTION("""COMPUTED_VALUE"""),"downtown B/D/F/M platform to mezzanine for access to street and N/Q/R/W service") -> downtown B/D/F/M platform to mezzanine for access to street and N/Q/R/W service | V25: =IFERROR(__xludf.DUMMYFUNCTION("""COMPUTED_VALUE"""),"POINT (-73.987686 40.75006)") -> POINT (-73.987686 40.75006)
A26: =IFERROR(__xludf.DUMMYFUNCTION("""COMPUTED_VALUE"""),"Lexington Av/63 St") -> Lexington Av/63 St | B26: =IFERROR(__xludf.DUMMYFUNCTION("""COMPUTED_VALUE"""),"") | C26: =IFERROR(__xludf.DUMMYFUNCTION("""COMPUTED_VALUE"""),"") | D26: =IFERROR(__xludf.DUMMYFUNCTION("""COMPUTED_VALUE"""),"") | E26: =IFERROR(__xludf.DUMMYFUNCTION("""COMPUTED_VALUE"""),"") | F26: =IFERROR(__xludf.DUMMYFUNCTION("""COMPUTED_VALUE"""),"") | G26: =IFERROR(__xludf.DUMMYFUNCTION("""COMPUTED_VALUE"""),"") | H26: =IFERROR(__xludf.DUMMYFUNCTION("""COMPUTED_VALUE"""),"↗️") -> ↗️ | I26: =IFERROR(__xludf.DUMMYFUNCTION("""COMPUTED_VALUE"""),32782.0) -> 32782 | J26: =IFERROR(__xludf.DUMMYFUNCTION("""COMPUTED_VALUE"""),46107.0) -> 46107 | K26: =IFERROR(__xludf.DUMMYFUNCTION("""COMPUTED_VALUE"""),22.0) -> 22 | L26: =IFERROR(__xludf.DUMMYFUNCTION("""COMPUTED_VALUE"""),"YES") -> YES | M26: =IFERROR(__xludf.DUMMYFUNCTION("""COMPUTED_VALUE"""),"NYCT") -> NYCT | N26: =IFERROR(__xludf.DUMMYFUNCTION("""COMPUTED_VALUE"""),"KONE") -> KONE | O26: =IFERROR(__xludf.DUMMYFUNCTION("""COMPUTED_VALUE"""),"YES") -> YES | P26: =IFERROR(__xludf.DUMMYFUNCTION("""COMPUTED_VALUE"""),"NO") -> NO | Q26: =IFERROR(__xludf.DUMMYFUNCTION("""COMPUTED_VALUE"""),"NO") -> NO | R26: =IFERROR(__xludf.DUMMYFUNCTION("""COMPUTED_VALUE"""),"25'11 3/4") -> 25'11 3/4 | S26: =IFERROR(__xludf.DUMMYFUNCTION("""COMPUTED_VALUE"""),91.0) -> 91 | T26: =IFERROR(__xludf.DUMMYFUNCTION("""COMPUTED_VALUE"""),"40'") -> 40' | U26: =IFERROR(__xludf.DUMMYFUNCTION("""COMPUTED_VALUE"""),"intermediate mezzanine (Lexington Ave & 63 St) to lower mezzanine") -> intermediate mezzanine (Lexington Ave & 63 St) to lower mezzanine | V26: =IFERROR(__xludf.DUMMYFUNCTION("""COMPUTED_VALUE"""),"POINT (-73.967285 40.76518)") -> POINT (-73.967285 40.76518)
A27: =IFERROR(__xludf.DUMMYFUNCTION("""COMPUTED_VALUE"""),"Lexington Av/63 St") -> Lexington Av/63 St | B27: =IFERROR(__xludf.DUMMYFUNCTION("""COMPUTED_VALUE"""),"") | C27: =IFERROR(__xludf.DUMMYFUNCTION("""COMPUTED_VALUE"""),"") | D27: =IFERROR(__xludf.DUMMYFUNCTION("""COMPUTED_VALUE"""),"") | E27: =IFERROR(__xludf.DUMMYFUNCTION("""COMPUTED_VALUE"""),"") | F27: =IFERROR(__xludf.DUMMYFUNCTION("""COMPUTED_VALUE"""),"") | G27: =IFERROR(__xludf.DUMMYFUNCTION("""COMPUTED_VALUE"""),"") | H27: =IFERROR(__xludf.DUMMYFUNCTION("""COMPUTED_VALUE"""),"↗️") -> ↗️ | I27: =IFERROR(__xludf.DUMMYFUNCTION("""COMPUTED_VALUE"""),32782.0) -> 32782 | J27: =IFERROR(__xludf.DUMMYFUNCTION("""COMPUTED_VALUE"""),46107.0) -> 46107 | K27: =IFERROR(__xludf.DUMMYFUNCTION("""COMPUTED_VALUE"""),22.0) -> 22 | L27: =IFERROR(__xludf.DUMMYFUNCTION("""COMPUTED_VALUE"""),"YES") -> YES | M27: =IFERROR(__xludf.DUMMYFUNCTION("""COMPUTED_VALUE"""),"NYCT") -> NYCT | N27: =IFERROR(__xludf.DUMMYFUNCTION("""COMPUTED_VALUE"""),"KONE") -> KONE | O27: =IFERROR(__xludf.DUMMYFUNCTION("""COMPUTED_VALUE"""),"YES") -> YES | P27: =IFERROR(__xludf.DUMMYFUNCTION("""COMPUTED_VALUE"""),"NO") -> NO | Q27: =IFERROR(__xludf.DUMMYFUNCTION("""COMPUTED_VALUE"""),"NO") -> NO | R27: =IFERROR(__xludf.DUMMYFUNCTION("""COMPUTED_VALUE"""),"18'10 5/8") -> 18'10 5/8 | S27: =IFERROR(__xludf.DUMMYFUNCTION("""COMPUTED_VALUE"""),65.0) -> 65 | T27: =IFERROR(__xludf.DUMMYFUNCTION("""COMPUTED_VALUE"""),"40'") -> 40' | U27: =IFERROR(__xludf.DUMMYFUNCTION("""COMPUTED_VALUE"""),"lower mezzanine (Lexington Ave & 63 St) to downtown platform") -> lower mezzanine (Lexington Ave & 63 St) to downtown platform | V27: =IFERROR(__xludf.DUMMYFUNCTION("""COMPUTED_VALUE"""),"POINT (-73.96745 40.765236)") -> POINT (-73.96745 40.765236)
A28: =IFERROR(__xludf.DUMMYFUNCTION("""COMPUTED_VALUE"""),"59 St") -> 59 St | B28: =IFERROR(__xludf.DUMMYFUNCTION("""COMPUTED_VALUE"""),"4 Av Line") -> 4 Av Line | C28: =IFERROR(__xludf.DUMMYFUNCTION("""COMPUTED_VALUE"""),"Brooklyn") -> Brooklyn | D28: =IFERROR(__xludf.DUMMYFUNCTION("""COMPUTED_VALUE"""),"Sunset Park") -> Sunset Park | E28: =IFERROR(__xludf.DUMMYFUNCTION("""COMPUTED_VALUE"""),5652.0) -> 5652 | F28: =IFERROR(__xludf.DUMMYFUNCTION("""COMPUTED_VALUE"""),2952891.0) -> 2952891 | G28: =IFERROR(__xludf.DUMMYFUNCTION("""COMPUTED_VALUE"""),112.0) -> 112 | H28: =IFERROR(__xludf.DUMMYFUNCTION("""COMPUTED_VALUE"""),"↗️") -> ↗️ | I28: =IFERROR(__xludf.DUMMYFUNCTION("""COMPUTED_VALUE"""),22965.0) -> 22965 | J28: =IFERROR(__xludf.DUMMYFUNCTION("""COMPUTED_VALUE"""),45519.0) -> 45519 | K28: =IFERROR(__xludf.DUMMYFUNCTION("""COMPUTED_VALUE"""),22.0) -> 22 | L28: =IFERROR(__xludf.DUMMYFUNCTION("""COMPUTED_VALUE"""),"YES") -> YES | M28: =IFERROR(__xludf.DUMMYFUNCTION("""COMPUTED_VALUE"""),"NYCT") -> NYCT | N28: =IFERROR(__xludf.DUMMYFUNCTION("""COMPUTED_VALUE"""),"OK") -> OK | O28: =IFERROR(__xludf.DUMMYFUNCTION("""COMPUTED_VALUE"""),"YES") -> YES | P28: =IFERROR(__xludf.DUMMYFUNCTION("""COMPUTED_VALUE"""),"NO") -> NO | Q28: =IFERROR(__xludf.DUMMYFUNCTION("""COMPUTED_VALUE"""),"NO") -> NO | R28: =IFERROR(__xludf.DUMMYFUNCTION("""COMPUTED_VALUE"""),"50'") -> 50' | S28: =IFERROR(__xludf.DUMMYFUNCTION("""COMPUTED_VALUE"""),172.0) -> 172 | T28: =IFERROR(__xludf.DUMMYFUNCTION("""COMPUTED_VALUE"""),40.0) -> 40 | U28: =IFERROR(__xludf.DUMMYFUNCTION("""COMPUTED_VALUE"""),"uptown 4/5 platform to uptown 6 platform") -> uptown 4/5 platform to uptown 6 platform | V28: =IFERROR(__xludf.DUMMYFUNCTION("""COMPUTED_VALUE"""),"POINT (-73.968254 40.762287)") -> POINT (-73.968254 40.762287)
A29: =IFERROR(__xludf.DUMMYFUNCTION("""COMPUTED_VALUE"""),"South Ferry") -> South Ferry | B29: =IFERROR(__xludf.DUMMYFUNCTION("""COMPUTED_VALUE"""),"") | C29: =IFERROR(__xludf.DUMMYFUNCTION("""COMPUTED_VALUE"""),"") | D29: =IFERROR(__xludf.DUMMYFUNCTION("""COMPUTED_VALUE"""),"") | E29: =IFERROR(__xludf.DUMMYFUNCTION("""COMPUTED_VALUE"""),"") | F29: =IFERROR(__xludf.DUMMYFUNCTION("""COMPUTED_VALUE"""),"") | G29: =IFERROR(__xludf.DUMMYFUNCTION("""COMPUTED_VALUE"""),"") | H29: =IFERROR(__xludf.DUMMYFUNCTION("""COMPUTED_VALUE"""),"↗️") -> ↗️ | I29: =IFERROR(__xludf.DUMMYFUNCTION("""COMPUTED_VALUE"""),39888.0) -> 39888 | J29: =IFERROR(__xludf.DUMMYFUNCTION("""COMPUTED_VALUE"""),42913.0) -> 42913 | K29: =IFERROR(__xludf.DUMMYFUNCTION("""COMPUTED_VALUE"""),22.0) -> 22 | L29: =IFERROR(__xludf.DUMMYFUNCTION("""COMPUTED_VALUE"""),"YES") -> YES | M29: =IFERROR(__xludf.DUMMYFUNCTION("""COMPUTED_VALUE"""),"NYCT") -> NYCT | N29: =IFERROR(__xludf.DUMMYFUNCTION("""COMPUTED_VALUE"""),"KONE") -> KONE | O29: =IFERROR(__xludf.DUMMYFUNCTION("""COMPUTED_VALUE"""),"YES") -> YES | P29: =IFERROR(__xludf.DUMMYFUNCTION("""COMPUTED_VALUE"""),"NO") -> NO | Q29: =IFERROR(__xludf.DUMMYFUNCTION("""COMPUTED_VALUE"""),"NO") -> NO | R29: =IFERROR(__xludf.DUMMYFUNCTION("""COMPUTED_VALUE"""),"8030 mm (26' 4 1/8in)") -> 8030 mm (26' 4 1/8in) | S29: =IFERROR(__xludf.DUMMYFUNCTION("""COMPUTED_VALUE"""),109.0) -> 109 | T29: =IFERROR(__xludf.DUMMYFUNCTION("""COMPUTED_VALUE"""),"40in (NOMINAL), 996 mm") -> 40in (NOMINAL), 996 mm | U29: =IFERROR(__xludf.DUMMYFUNCTION("""COMPUTED_VALUE"""),"1/R/W mezzanine to platform for uptown 1 service") -> 1/R/W mezzanine to platform for uptown 1 service | V29: =IFERROR(__xludf.DUMMYFUNCTION("""COMPUTED_VALUE"""),"POINT (-74.013084 40.701675)") -> POINT (-74.013084 40.701675)
